Workbook

Sheet Balance Sheet
A1: Balance Sheet
A2: Update on 02-09-2026
A3: Assets | B3: TK | D3: Liabilities & Owners equity | E3: TK
A4: Bank Deposit | B4: =SUM(E68-(SUM(B5:B19))) -> 496785 | D4: Mohammad Jonaid 1 | E4: =sum('Payment Details'!C363+'Payment Details'!C422+'Payment Details'!C303+'Payment Details'!C242+'Payment Details'!C181+'Payment Details'!C123+'Payment Details'!C63, 'Payment Details'!C4) -> 35000
A5: Bank Charge as Maintenance Cost | B5: 317 | D5: Mohammad Jonaid 2 | E5: =sum('Payment Details'!C364+'Payment Details'!C423+'Payment Details'!C304+'Payment Details'!C243+'Payment Details'!C182+'Payment Details'!C124+'Payment Details'!C64, 'Payment Details'!C5) -> 35000
A6: Cash in Hand (Treasurer) | B6: 376984 | D6: Mohammad Jonaid 3 | E6: =sum('Payment Details'!C365+'Payment Details'!C424+'Payment Details'!C305+'Payment Details'!C244+'Payment Details'!C183+'Payment Details'!C125+'Payment Details'!C65, 'Payment Details'!C6) -> 35000
A7: Cash in Hand (Faysal) | B7: 8000 | D7: Abdullah Ibne Kabir Fahim 1 | E7: =sum('Payment Details'!C366+'Payment Details'!C425+'Payment Details'!C306+'Payment Details'!C245+'Payment Details'!C184+'Payment Details'!C126+'Payment Details'!C66, 'Payment Details'!C7) -> 35000
A8: Account Receivable-Faysal (Sale-1) | B8: =240000-'Faysal Sales Portfolio-1'!B91 -> 210000 | D8: Abdullah Ibne Kabir Fahim 2 | E8: =sum('Payment Details'!C367+'Payment Details'!C426+'Payment Details'!C307+'Payment Details'!C246+'Payment Details'!C185+'Payment Details'!C127+'Payment Details'!C67, 'Payment Details'!C8) -> 35000
A9: Account Receivable-Abdur Rahim (Sale-2) | B9: =121000-'A. Rahim Sales Portfolio-2'!B88 -> 80664 | D9: Abdur Rahim 1 | E9: =sum('Payment Details'!C368+'Payment Details'!C427+'Payment Details'!C308+'Payment Details'!C247+'Payment Details'!C186+'Payment Details'!C128+'Payment Details'!C68, 'Payment Details'!C9) -> 35000
A10: Account Receivable-Johir Jafory (Loan-04) | B10: 20000 | D10: Abdur Rahim 2 | E10: =sum('Payment Details'!C369+'Payment Details'!C428+'Payment Details'!C309+'Payment Details'!C248+'Payment Details'!C187+'Payment Details'!C129+'Payment Details'!C69, 'Payment Details'!C10) -> 35000
A11: Account Receivable-Harun (Sale-3) | B11: =244000-'Harun Sales Portfolio-3'!B94 -> 189000 | D11: MD Ariful Islam Riad 1 | E11: =sum('Payment Details'!C370+'Payment Details'!C429+'Payment Details'!C310+'Payment Details'!C249+'Payment Details'!C188+'Payment Details'!C130+'Payment Details'!C70, 'Payment Details'!C11) -> 35000
A12: Account Receivable-Salman (Sale-4) | B12: =40535-'Salman Sales Portfolio-4'!B88 -> 26935 | D12: MD Ariful Islam Riad 2 | E12: =sum('Payment Details'!C371+'Payment Details'!C430+'Payment Details'!C311+'Payment Details'!C250+'Payment Details'!C189+'Payment Details'!C131+'Payment Details'!C71, 'Payment Details'!C12) -> 35000
A13: Account Receivable-Minhaj (Sale-5) | B13: =290000-'Minhaj Sales Portfolio-5'!B89 -> 240000 | D13: MD Ariful Islam Riad 3 | E13: =sum('Payment Details'!C372+'Payment Details'!C431+'Payment Details'!C312+'Payment Details'!C251+'Payment Details'!C190+'Payment Details'!C132+'Payment Details'!C72, 'Payment Details'!C13) -> 35000
A14: Account Receivable-Sajid Mahmood (Loan-07) | B14: =30000-Loan!G55 -> 18000 | D14: MD Ariful Islam Riad 4 | E14: =sum('Payment Details'!C373+'Payment Details'!C432+'Payment Details'!C313+'Payment Details'!C252+'Payment Details'!C191+'Payment Details'!C133+'Payment Details'!C73, 'Payment Details'!C14) -> 35000
A15: Account Receivable-Faysal (Loan-10) | B15: =20000-Loan!G82 -> 20000 | D15: Emdadullah 1 | E15: =sum('Payment Details'!C374+'Payment Details'!C433+'Payment Details'!C314+'Payment Details'!C253+'Payment Details'!C192+'Payment Details'!C134+'Payment Details'!C74, 'Payment Details'!C15) -> 35000
A16: Account Receivable-Fahim (Loan-11) | B16: =50000-Loan!G90 -> 50000 | D16: Johir Raihan 1 | E16: =sum('Payment Details'!C375+'Payment Details'!C434+'Payment Details'!C315+'Payment Details'!C254+'Payment Details'!C193+'Payment Details'!C135+'Payment Details'!C75, 'Payment Details'!C16) -> 35000
A17: Account Receivable-Riad (Sale-6) | B17: =193720-'Riad Sales Portfolio-6'!B89 -> 177570 | D17: Johir Raihan 2 | E17: =sum('Payment Details'!C376+'Payment Details'!C435+'Payment Details'!C316+'Payment Details'!C255+'Payment Details'!C194+'Payment Details'!C136+'Payment Details'!C76, 'Payment Details'!C17) -> 35000
A18: Account Receivable- Sharif Mahmud (Loan-12) | B18: =15000-Loan!G98 -> 15000 | D18: Johir Raihan 3 | E18: =sum('Payment Details'!C377+'Payment Details'!C436+'Payment Details'!C317+'Payment Details'!C256+'Payment Details'!C195+'Payment Details'!C137+'Payment Details'!C77, 'Payment Details'!C18) -> 35000
A19: Account Receivable- Neyamot Ullah (Loan-13) | B19: =7000-Loan!G106 -> 7000 | D19: Md. Sajid Mahmud 1 | E19: =sum('Payment Details'!C378+'Payment Details'!C437+'Payment Details'!C318+'Payment Details'!C257+'Payment Details'!C196+'Payment Details'!C138+'Payment Details'!C78, 'Payment Details'!C19) -> 35000
D20: Md. Sajid Mahmud 2 | E20: =sum('Payment Details'!C379+'Payment Details'!C438+'Payment Details'!C319+'Payment Details'!C258+'Payment Details'!C197+'Payment Details'!C139+'Payment Details'!C79, 'Payment Details'!C20) -> 35000
D21: Md. Sajid Mahmud 3 | E21: =sum('Payment Details'!C380+'Payment Details'!C439+'Payment Details'!C320+'Payment Details'!C259+'Payment Details'!C198+'Payment Details'!C140+'Payment Details'!C80, 'Payment Details'!C21) -> 35000
D22: Md. Sajid Mahmud 4 | E22: =sum('Payment Details'!C381+'Payment Details'!C440+'Payment Details'!C321+'Payment Details'!C260+'Payment Details'!C199+'Payment Details'!C141+'Payment Details'!C81, 'Payment Details'!C22) -> 35000
D23: MD. Faysal Ahmed 1 | E23: =sum('Payment Details'!C382+'Payment Details'!C441+'Payment Details'!C322+'Payment Details'!C261+'Payment Details'!C200+'Payment Details'!C142+'Payment Details'!C82, 'Payment Details'!C23) -> 25000
D24: MD. Faysal Ahmed 2 | E24: =sum('Payment Details'!C383+'Payment Details'!C442+'Payment Details'!C323+'Payment Details'!C262+'Payment Details'!C201+'Payment Details'!C143+'Payment Details'!C83, 'Payment Details'!C24) -> 25000
D25: MD. Faysal Ahmed 3 | E25: =sum('Payment Details'!C384+'Payment Details'!C443+'Payment Details'!C324+'Payment Details'!C263+'Payment Details'!C202+'Payment Details'!C144+'Payment Details'!C84, 'Payment Details'!C25) -> 25000
D26: Johir Jafory 1 | E26: =sum('Payment Details'!C385+'Payment Details'!C444+'Payment Details'!C325+'Payment Details'!C264+'Payment Details'!C203+'Payment Details'!C145+'Payment Details'!C85, 'Payment Details'!C26) -> 20000
D27: Johir Jafory 2 | E27: =sum('Payment Details'!C386+'Payment Details'!C445+'Payment Details'!C326+'Payment Details'!C265+'Payment Details'!C204+'Payment Details'!C146+'Payment Details'!C86, 'Payment Details'!C27) -> 20000
D28: Johir Jafory 3 | E28: =sum('Payment Details'!C387+'Payment Details'!C446+'Payment Details'!C327+'Payment Details'!C266+'Payment Details'!C205+'Payment Details'!C147+'Payment Details'!C87, 'Payment Details'!C28) -> 20000
D29: Md. Jahid Bin Amin 1 | E29: =sum('Payment Details'!C388+'Payment Details'!C447+'Payment Details'!C328+'Payment Details'!C267+'Payment Details'!C206+'Payment Details'!C148+'Payment Details'!C88, 'Payment Details'!C29) -> 35000
D30: Md. Jahid Bin Amin 2 | E30: =sum('Payment Details'!C389+'Payment Details'!C448+'Payment Details'!C329+'Payment Details'!C268+'Payment Details'!C207+'Payment Details'!C149+'Payment Details'!C89, 'Payment Details'!C30) -> 35000
D31: Rakibul Hasan 1 | E31: =sum('Payment Details'!C390+'Payment Details'!C449+'Payment Details'!C330+'Payment Details'!C269+'Payment Details'!C208+'Payment Details'!C150+'Payment Details'!C90, 'Payment Details'!C31) -> 35000
... D56: Atiqure Rahman 1 | E56: =sum('Payment Details'!C415+'Payment Details'!C474+'Payment Details'!C355+'Payment Details'!C294+'Payment Details'!C233+'Payment Details'!C175+'Payment Details'!C115, 'Payment Details'!C56) -> 35000
D61: Combined equity from sale-01 | E61: 52500
D62: Combined equity from sale-02 | E62: 21000
D63: Combined equity from sale-03 | E63: 44000
D64: Combined equity from sale-04 | E64: 7035
D65: Combined equity from sale-05 | E65: 40000
D66: Combined equity from sale-06 | E66: 26720
A68: Total | B68: =sum(B4:B42) -> 1936255 | D68: Total | E68: =sum(E4:E67) -> 1936255

Sheet Payment Details
A3: ID | B3: Name | C3: Payment | D3: Payment Remarks | E3: Payment Date | F3: Payment Reference
A4: QIA_01202601 | B4: Mohammad Jonaid
A5: QIA_01202602 | B5: Mohammad Jonaid
A6: QIA_01202603 | B6: Mohammad Jonaid
A7: QIA_01202604 | B7: Abdullah Ibne Kabir Fahim
A8: QIA_01202605 | B8: Abdullah Ibne Kabir Fahim
A9: QIA_01202606 | B9: Abdur Rahim
A10: QIA_01202607 | B10: Abdur Rahim
A11: QIA_01202608 | B11: MD Ariful Islam Riad
A12: QIA_01202609 | B12: MD Ariful Islam Riad
A13: QIA_01202610 | B13: MD Ariful Islam Riad
A14: QIA_01202611 | B14: MD Ariful Islam Riad
A15: QIA_01202612 | B15: Emdadullah
... A37: QIA_01202634 | B37: Rakibul Hasan
A38: QIA_01202635 | B38: MD Neyamot Ullah | C38: 5000 | D38: On-time | E38: 01/09/2026 | F38: 9626090100145479
A39: QIA_01202636 | B39: Minhajur Rahman
A40: QIA_01202637 | B40: Minhajur Rahman
A41: QIA_01202638 | B41: Minhajur Rahman
A42: QIA_01202639 | B42: Minhajur Rahman
A43: QIA_01202640 | B43: Abdur Rahim
A44: QIA_01202641 | B44: Abdur Rahim
A45: QIA_01202642 | B45: MD Ariful Islam Riad
A46: QIA_01202643 | B46: Johir Jafory
A47: QIA_01202644 | B47: Abdullah Ibne Kabir Fahim
A48: QIA_01202645 | B48: Abdullah Ibne Kabir Fahim
A49: QIA_01202646 | B49: Rakibul Hasan
A50: QIA_01202647 | B50: Johir Raihan
... A56: QIA_01202653 | B56: Atiqure Rhaman
A62: ID | B62: Name | C62: Payment | D62: Payment Remarks | E62: Payment Date | F62: Payment Reference
A63: QIA_01202601 | B63: Mohammad Jonaid | C63: 5000 | D63: On-time | E63: 05/08/2026 | F63: 9626080500015261
A64: QIA_01202602 | B64: Mohammad Jonaid | C64: 5000 | D64: On-time | E64: 05/08/2026 | F64: 9626080500015261
A65: QIA_01202603 | B65: Mohammad Jonaid | C65: 5000 | D65: On-time | E65: 05/08/2026 | F65: 9626080500015261
A66: QIA_01202604 | B66: Abdullah Ibne Kabir Fahim | C66: 5000 | D66: On-time | E66: 03/08/2026 | F66: 9626080300010003
A67: QIA_01202605 | B67: Abdullah Ibne Kabir Fahim | C67: 5000 | D67: On-time | E67: 03/08/2026 | F67: 9626080300010003
A68: QIA_01202606 | B68: Abdur Rahim | C68: 5000 | D68: On-time | E68: 04/08/2026 | F68: 9626080400132741
A69: QIA_01202607 | B69: Abdur Rahim | C69: 5000 | D69: On-time | E69: 04/08/2026 | F69: 9626080400132741
A70: QIA_01202608 | B70: MD Ariful Islam Riad | C70: 5000 | D70: On-time | E70: 03/08/2026 | F70: 9626080300113790
A71: QIA_01202609 | B71: MD Ariful Islam Riad | C71: 5000 | D71: On-time | E71: 03/08/2026 | F71: 9626080300113790
A72: QIA_01202610 | B72: MD Ariful Islam Riad | C72: 5000 | D72: On-time | E72: 03/08/2026 | F72: 9626080300113790
A73: QIA_01202611 | B73: MD Ariful Islam Riad | C73: 5000 | D73: On-time | E73: 03/08/2026 | F73: 9626080300113790
...

Sheet Costsখরচ
A1: Sl. | B1: Title | C1: Date | D1: Amount | E1: Paid to
A2: 1 | B2: Form printing | C2: 46024 | D2: 200 | E2: Fahim
A3: 2 | B3: Cheque Book | C3: 46084 | D3: 100 | E3: Fahim
A4: 3 | B4: Rickshaw fare (Return from bank) | C4: 46115 | D4: 40 | E4: Fahim
A5: 4 | B5: Fare (During Sales-1) | C5: 46298 | D5: 100 | E5: Jahid Bin Amin
A6: 5 | B6: Fare (Bank-Madrasa-Bank) | C6: 46331 | D6: 150 | E6: Fahim
A7: 6 | B7: Fare (Bank-Home) | C7: 18/6/2026 | D7: 120 | E7: Jahid Bin Amin
D19: =SUM(D2:D18) -> 710

Sheet Partner List
A1: SL | B1: Name | C1: No of Share | D1: TK (Form Fee) | E1: Deposit amount so far | F1: Due Amount till August | G1: Bank Account Info
A2: 1 | B2: Abdullah Ibne Kabir Fahim | C2: 4 | D2: 100 | E2: =SUM('Balance Sheet'!E48+'Balance Sheet'!E47+'Balance Sheet'!E8+'Balance Sheet'!E7) -> 140000 | F2: =C2*40000-E2 -> 20000 | G2: 🏦 ব্যাংকের নাম: Islami Bank Bangladesh PLC.
A3: 2 | B3: Md. Sajid Mahmud | C3: 4 | D3: 100 | E3: =SUM('Balance Sheet'!E19:E22) -> 140000 | F3: =C3*40000-E3 -> 20000
A4: 3 | B4: Md. Jahid Bin Amin | C4: 2 | D4: 100 | E4: =SUM('Balance Sheet'!E29:E30) -> 70000 | F4: =C4*40000-E4 -> 10000 | G4: 🏢 শাখা: Aftabnagar Sub-Branch, Badda, Dhaka
A5: 4 | B5: Ariful Islam Riad | C5: 5 | D5: 100 | E5: =SUM('Balance Sheet'!E11:E14,'Balance Sheet'!E45) -> 175000 | F5: =C5*40000-E5 -> 25000
A6: 5 | B6: Rakibul Hasan | C6: 5 | D6: 100 | E6: =SUM('Balance Sheet'!E31,'Balance Sheet'!E33,'Balance Sheet'!E36,'Balance Sheet'!E37,'Balance Sheet'!E49) -> 175000 | F6: =C6*40000-E6 -> 25000 | G6: 📍 শাখার ঠিকানা: Rajlaxmi Complex, Aftabnagar, H-29/W-37, Badda Main Road, PS: Badda, Dhaka
A7: 6 | B7: MD Faysal Ahmed | C7: 3 | D7: 100 | E7: =SUM('Balance Sheet'!E23:E25) -> 75000 | F7: =C7*40000-E7 -> 45000
A8: 7 | B8: Johir Raihan | C8: 9 | D8: 100 | E8: =SUM('Balance Sheet'!E16:E18,'Balance Sheet'!E50:E52, 'Balance Sheet'!E53:E55) -> 300000 | F8: =C8*40000-E8 -> 60000 | G8: 👤 Account Name: Md. Faysal Ahmed, Sajid, Fahim, Riad and Jahirul Islam
A9: 8 | B9: Johir Jafory | C9: 4 | D9: 100 | E9: =SUM('Balance Sheet'!E26:E28,'Balance Sheet'!E46) -> 70000 | F9: =C9*40000-E9 -> 90000
A10: 9 | B10: Harun Or Rosid | C10: 1 | D10: 100 | E10: =SUM('Balance Sheet'!E35) -> 35000 | F10: =C10*40000-E10 -> 5000 | G10: 🔢 Account Number: 20506470200276102
A11: 10 | B11: Abdur Rahim | C11: 4 | D11: 100 | E11: =SUM('Balance Sheet'!E9:E10,'Balance Sheet'!E43:E44) -> 140000 | F11: =C11*40000-E11 -> 20000
A12: 11 | B12: Sharif Mahmood | C12: 1 | D12: Due | E12: =SUM('Balance Sheet'!E34) -> 35000 | F12: =C12*40000-E12 -> 5000 | G12: 📅 Opening Date: 19 February 2026
A13: 12 | B13: Mohammad Jonaid | C13: 3 | D13: 100 | E13: =SUM('Balance Sheet'!E4:E6) -> 105000 | F13: =C13*40000-E13 -> 15000
A14: 13 | B14: Emdadullah | C14: 1 | D14: 100 | E14: =SUM('Balance Sheet'!E15) -> 35000 | F14: =C14*40000-E14 -> 5000 | G14: 🆔 Customer ID: 6470700013312
A15: 14 | B15: Mamun Hossain | C15: 1 | D15: 100 | E15: =SUM('Balance Sheet'!E32) -> 35000 | F15: =C15*40000-E15 -> 5000
A16: 15 | B16: MD Neyamot Ullah | C16: 1 | D16: Due | E16: =SUM('Balance Sheet'!E38) -> 40000 | F16: =C16*40000-E16 -> 0
A17: 16 | B17: Minhajur Rahman | C17: 4 | D17: 100 | E17: =SUM('Balance Sheet'!E40:E42,'Balance Sheet'!E39) -> 140000 | F17: =C17*40000-E17 -> 20000
A18: 17 | B18: Atiqure Rahman | C18: 1 | D18: 100 | E18: =SUM('Balance Sheet'!E56) -> 35000 | F18: =C18*40000-E18 -> 5000
C19: =SUM(Share_Info[[#DATA],[#TOTALS],[No of Share]]) -> 53 | D19: =SUM(D2:D18) -> 1500 | E19: =SUM(Share_Info[[#DATA],[#TOTALS],[Deposit amount so far]]) -> 1745000 | F19: =SUM(Share_Info[[#DATA],[#TOTALS],[Due Amount till August]]) -> 375000

Sheet Loan
A2: Loan-01
A3: Date | B3: Details | C3: TK | E3: Date | F3: Details (Payment) | G3: TK
A4: 15/03/2026 | B4: Account Receiveable (Fahim) | C4: 10000 | E4: 46361 | G4: 10000
G7: =SUM(G4:G6) -> 10000 | H7: Paid
A10: Loan-02
A11: Date | B11: Details | C11: TK | E11: Date | F11: Details (Payment) | G11: TK
A12: 15/03/2026 | B12: Account Receiveable (Johir Raihan) | C12: 15000 | E12: 46361 | G12: 15000
G15: =SUM(G12:G14) -> 15000 | H15: Paid
A18: Loan-03
A19: Date | B19: Details | C19: TK | E19: Date | F19: Details (Payment) | G19: TK
A20: 46057 | B20: Account Receiveable (Riad) | C20: 30000 | E20: 46177 | F20: Payment-1 | G20: 10000
E21: 16/05/2026 | F21: Payment-2 | G21: 10000
E22: 22/05/2026 | F22: Payment-3 | G22: 10000
G23: =SUM(G20:G22) -> 30000 | H23: Paid
A26: Loan-04
A27: Date | B27: Details | C27: TK | E27: Date | F27: Details (Payment) | G27: TK
A28: 46116 | B28: Account Receiveable (J. Jafory) | C28: 20000
G31: =SUM(G28:G30) -> 0
A34: Loan-05
A35: Date | B35: Details | C35: TK | E35: Date | F35: Details (Payment) | G35: TK
A36: 46238 | B36: Account Receiveable (J. Raihan) | C36: 10000 | E36: 28/04/2026 | F36: 3426042800006912 | G36: 10000
G39: =SUM(G36:G38) -> 10000 | H39: Paid
A42: Loan-06
A43: Date | B43: Details | C43: TK | E43: Date | F43: Details (Payment) | G43: TK
A44: 21/04/2026 | B44: Account Receiveable (Fahim) | C44: 20000 | E44: 46059 | F44: 3426060200100351 | G44: 20000
G47: =SUM(G44:G46) -> 20000 | H47: Paid
A50: Loan-07
A51: Date | B51: Details | C51: TK | E51: Date | F51: Details (Payment) | G51: TK
A52: 22/05/2026 | B52: Account Receiveable (Sajid) | C52: 30000 | E52: 10.08.2026 | F52: Cash (Reciept No: 28) | G52: 12000
G55: =SUM(G52:G54) -> 12000
A59: Loan-08
A60: Date | B60: Details | C60: TK | E60: Date | F60: Details (Payment) | G60: TK
A61: 22/05/2026 | B61: Account Receiveable (A. Rahim) | C61: 15000 | E61: 27/06/2026 | F61: Cash | G61: 15000
G64: =SUM(G61:G63) -> 15000 | H64: Paid
A68: Loan-09
A69: Date | B69: Details | C69: TK | E69: Date | F69: Details (Payment) | G69: TK
A70: 22/05/2026 | B70: Account Receiveable (Riad) | C70: 20000 | E70: 46181 | F70: Cash (Reciept No: 25) | G70: 20000
G73: =SUM(G70:G72) -> 20000 | H73: Paid
A77: Loan-10
A78: Date | B78: Details | C78: TK | E78: Date | F78: Details (Payment) | G78: TK
...

Sheet Faysal Sales Portfolio-1
A1: Sales Portfolio-1
A4: Invoice No. | B4: QIA-INV-01
A5: Issue Date | B5: 46091
A6: Customer Name | B6: MD Faysal Ahmed
A7: Phone Number | B7: 01608-775580
A8: Adress | B8: Aftabnagar, Dhaka
A11: Sl | B11: Item Description | C11: Quantity | D11: Unit Price | E11: Total Price | F11: Cost Price | G11: Gross Profit
A12: 1 | B12: Hero XOOM 125R FI | C12: 1 | D12: 260500 | E12: 260500 | F12: 208000 | G12: =E12-F12 -> 52500
A13: Grand Total: (Two Lakh Sixty Thousand Five Hundred Taka Only) | E13: 260500
D14: Amount Paid | E14: 20500
D15: Amount Due | E15: 240000
A19: ID | B19: Name | C19: Invested Amount | D19: Estimated Gross Profit
A20: QIA_01202601 | B20: Mohammad Jonaid | C20: 5200 | D20: 1312.5
A21: QIA_01202602 | B21: Mohammad Jonaid | C21: 5200 | D21: 1312.5
A22: QIA_01202603 | B22: Mohammad Jonaid | C22: 5200 | D22: 1312.5
A23: QIA_01202604 | B23: Abdullah Ibne Kabir Fahim | C23: 5200 | D23: 1312.5
A24: QIA_01202605 | B24: Abdullah Ibne Kabir Fahim | C24: 5200 | D24: 1312.5
A25: QIA_01202606 | B25: Abdur Rahim | C25: 5200 | D25: 1312.5
A26: QIA_01202607 | B26: Abdur Rahim | C26: 5200 | D26: 1312.5
A27: QIA_01202608 | B27: MD Ariful Islam Riad | C27: 5200 | D27: 1312.5
A28: QIA_01202609 | B28: MD Ariful Islam Riad | C28: 5200 | D28: 1312.5
A29: QIA_01202610 | B29: MD Ariful Islam Riad | C29: 5200 | D29: 1312.5
A30: QIA_01202611 | B30: MD Ariful Islam Riad | C30: 5200 | D30: 1312.5
A31: QIA_01202612 | B31: Emdadullah | C31: 5200 | D31: 1312.5
... A59: QIA_01202640 | B59: Abdullah Ibne Kabir Fahim | C59: 5200 | D59: 1312.5
A60: Total | C60: =SUM(C20:C59) -> 208000 | D60: =SUM(D20:D59) -> 52500
A65: Installment Payment Schedule (24 Months)
A66: Month | B66: Installment (BDT) | C66: Remaining Due (BDT) | D66: Remarks
A67: 46113 | B67: 10000 | C67: =240000-SUM(B44:B67) -> 230000 | D67: N/A
A68: 46143 | B68: 10000 | C68: =240000-SUM(B45:B68) -> 220000 | D68: 3426050600158442
A69: 46174 | B69: 10000 | C69: =240000-SUM(B46:B69) -> 210000 | D69: Adjusted to Loan-10
A70: 46204 | C70: =240000-SUM(B47:B70) -> 210000
A71: 46235 | C71: =240000-SUM(B48:B71) -> 210000
A72: 46266 | C72: =240000-SUM(B49:B72) -> 210000
A73: 46296 | C73: =240000-SUM(B50:B73) -> 210000
A74: 46327 | C74: =240000-SUM(B51:B74) -> 210000
A75: 46357 | C75: =240000-SUM(B52:B75) -> 210000
A76: 46388 | C76: =240000-SUM(B53:B76) -> 210000
A77: 46419 | C77: =240000-SUM(B54:B77) -> 210000
A78: 46447 | C78: =240000-SUM(B55:B78) -> 210000
...

Sheet A. Rahim Sales Portfolio-2
A1: Sales Portfolio-2
A4: Invoice No. | B4: QIA-INV-02
A5: Issue Date | B5: 46117
A6: Customer Name | B6: Hafsa Begum
A7: Phone Number | B7: 1511367388
A8: Adress | B8: Pirojpur Sadar, Pirojpur
A11: Sl | B11: Item Description | C11: Quantity | D11: Unit Price | E11: Total Price | F11: Cost Price | G11: Gross Profit
A12: 1 | B12: Door-Window, Angle, Tin, Rod | C12: 1 | D12: 1,23,050 | E12: 1,23,050 | F12: 1,00,000 | G12: 21000
A13: Grand Total: (One Lakh Twenty Three Thousand Fifty Taka Only) | E13: 1,23,050
D14: Amount Paid | E14: 2050
D15: Amount Due | E15: 1,21,000
A19: ID | B19: Name | C19: Invested Amount | D19: Estimated Gross Profit
A20: QIA_01202601 | B20: Mohammad Jonaid | C20: 2040.81 | D20: 428.58
A21: QIA_01202602 | B21: Mohammad Jonaid | C21: 2040.81 | D21: 428.58
A22: QIA_01202603 | B22: Mohammad Jonaid | C22: 2040.81 | D22: 428.58
A23: QIA_01202604 | B23: Abdullah Ibne Kabir Fahim | C23: 2040.81 | D23: 428.58
A24: QIA_01202605 | B24: Abdullah Ibne Kabir Fahim | C24: 2040.81 | D24: 428.58
A25: QIA_01202606 | B25: Abdur Rahim | C25: 2040.81 | D25: 428.58
A26: QIA_01202607 | B26: Abdur Rahim | C26: 2040.81 | D26: 428.58
A27: QIA_01202608 | B27: MD Ariful Islam Riad | C27: 2040.81 | D27: 428.58
A28: QIA_01202609 | B28: MD Ariful Islam Riad | C28: 2040.81 | D28: 428.58
A29: QIA_01202610 | B29: MD Ariful Islam Riad | C29: 2040.81 | D29: 428.58
A30: QIA_01202611 | B30: MD Ariful Islam Riad | C30: 2040.81 | D30: 428.58
A31: QIA_01202612 | B31: Emdadullah | C31: 2040.81 | D31: 428.58
... A68: QIA_01202649 | B68: Johir Raihan | C68: 2040.81 | D68: 428.58
A69: Total | C69: =SUM(C20:C68) -> 99999.69 | D69: =SUM(D20:D68) -> 21000.42
A74: Installment Payment Schedule (12 Months)
A75: Month | B75: Installment (BDT) | C75: Remaining Due (BDT) | D75: Remarks
A76: 46143 | B76: 10084 | C76: =121000-Sum(B44:B76) -> 110916 | D76: 3426050300163061
A77: 46174 | B77: 10084 | C77: =121000-Sum(B45:B77) -> 100832 | D77: 3426052200103937
A78: 46204 | B78: 10084 | C78: =121000-Sum(B46:B78) -> 90748 | D78: Cash (Reciept No: 17)
A79: 46235 | B79: 10084 | C79: =121000-Sum(B47:B79) -> 80664 | D79: 9626080400132741
A80: 46266 | C80: =121000-Sum(B48:B80) -> 80664
A81: 46296 | C81: =121000-Sum(B49:B81) -> 80664
A82: 46327 | C82: =121000-Sum(B50:B82) -> 80664
A83: 46357 | C83: =121000-Sum(B51:B83) -> 80664
A84: 46388 | C84: =121000-Sum(B52:B84) -> 80664
A85: 46419 | C85: =121000-Sum(B53:B85) -> 80664
A86: 46447 | C86: =121000-Sum(B54:B86) -> 80664
A87: 46478 | C87: =121000-Sum(B55:B87) -> 80664 | D87: Final Payment
...

Sheet Harun Sales Portfolio-3
A1: Sales Portfolio-3
A4: Invoice No. | B4: QIA-INV-03
A5: Issue Date | B5: 46118
A6: Customer Name | B6: Harun Or Rosid
A7: Phone Number | B7: 1842824970
A8: Adress | B8: Chauddagram, Dhaka
A11: Sl | B11: Item Description | C11: Quantity | D11: Unit Price | E11: Total Price | F11: Cost Price | G11: Gross Profit
A12: 1 | B12: Gold | C12: 15 Ana | D12: 16266.67 | E12: 2,44,000 | F12: 2,00,000 | G12: 44000
A13: Grand Total: (Two Lac Forty Four Thousand Taka Only)
D14: Amount Paid | E14: 0
D15: Amount Due | E15: 2,44,000
A19: ID | B19: Name | C19: Invested Amount | D19: Estimated Gross Profit
A20: QIA_01202601 | B20: Mohammad Jonaid | C20: 4081.64 | D20: 897.96
A21: QIA_01202602 | B21: Mohammad Jonaid | C21: 4081.64 | D21: 897.96
A22: QIA_01202603 | B22: Mohammad Jonaid | C22: 4081.64 | D22: 897.96
A23: QIA_01202604 | B23: Abdullah Ibne Kabir Fahim | C23: 4081.64 | D23: 897.96
A24: QIA_01202605 | B24: Abdullah Ibne Kabir Fahim | C24: 4081.64 | D24: 897.96
A25: QIA_01202606 | B25: Abdur Rahim | C25: 4081.64 | D25: 897.96
A26: QIA_01202607 | B26: Abdur Rahim | C26: 4081.64 | D26: 897.96
A27: QIA_01202608 | B27: MD Ariful Islam Riad | C27: 4081.64 | D27: 897.96
A28: QIA_01202609 | B28: MD Ariful Islam Riad | C28: 4081.64 | D28: 897.96
A29: QIA_01202610 | B29: MD Ariful Islam Riad | C29: 4081.64 | D29: 897.96
A30: QIA_01202611 | B30: MD Ariful Islam Riad | C30: 4081.64 | D30: 897.96
A31: QIA_01202612 | B31: Emdadullah | C31: 4081.64 | D31: 897.96
... A68: QIA_01202649 | B68: Johir Raihan | C68: 4081.64 | D68: 897.96
A69: Total | C69: =SUM(C20:C68) -> 200000.36 | D69: =SUM(D20:D68) -> 44000.04
A74: Installment Payment Schedule (18 Months)
A75: Month | B75: Installment (BDT) | C75: Remaining Due (BDT) | D75: Remarks
A76: 46143 | B76: 14000 | C76: =244000-Sum(B44:B76) -> 230000 | D76: 3426050400054338
A77: 46174 | B77: 14000 | C77: =244000-Sum(B45:B77) -> 216000 | D77: 3426052100154137
A78: 46204 | B78: 13500 | C78: =244000-Sum(B46:B78) -> 202500 | D78: Cash (Reciept No: 06)
A79: 46235 | B79: 13500 | C79: =244000-Sum(B47:B79) -> 189000 | D79: 9626080400034524
A80: 46266 | C80: =244000-Sum(B48:B80) -> 189000
A81: 46296 | C81: =244000-Sum(B49:B81) -> 189000
A82: 46327 | C82: =244000-Sum(B50:B82) -> 189000
A83: 46357 | C83: =244000-Sum(B51:B83) -> 189000
A84: 46388 | C84: =244000-Sum(B52:B84) -> 189000
A85: 46419 | C85: =244000-Sum(B53:B85) -> 189000
A86: 46447 | C86: =244000-Sum(B54:B86) -> 189000
A87: 46478 | C87: =244000-Sum(B55:B87) -> 189000
...

Sheet Salman Sales Portfolio-4
A1: Sales Portfolio-4
A4: Invoice No. | B4: QIA-INV-04
A5: Issue Date | B5: 46133
A6: Customer Name | B6: Salman
A7: Phone Number | B7: 1642086013
A8: Adress | B8: Tejgaon, Dhaka
A11: Sl | B11: Item Description | C11: Quantity | D11: Unit Price | E11: Total Price | F11: Cost Price | G11: Gross Profit
A12: 1 | B12: Gold (22K) | C12: 2 Ana | D12: 20267.5 | E12: 40535 | F12: 33500 | G12: =E12-F12 -> 7035
A13: Grand Total: (Forty Thousand Five Hundred Thirty Five Taka Only) | E13: 40535
D14: Amount Paid | E14: 0
D15: Amount Due | E15: 40535
A19: ID | B19: Name | C19: Invested Amount | D19: Estimated Gross Profit
A20: QIA_01202601 | B20: Mohammad Jonaid | C20: 683.68 | D20: 143.58
A21: QIA_01202602 | B21: Mohammad Jonaid | C21: 683.68 | D21: 143.58
A22: QIA_01202603 | B22: Mohammad Jonaid | C22: 683.68 | D22: 143.58
A23: QIA_01202604 | B23: Abdullah Ibne Kabir Fahim | C23: 683.68 | D23: 143.58
A24: QIA_01202605 | B24: Abdullah Ibne Kabir Fahim | C24: 683.68 | D24: 143.58
A25: QIA_01202606 | B25: Abdur Rahim | C25: 683.68 | D25: 143.58
A26: QIA_01202607 | B26: Abdur Rahim | C26: 683.68 | D26: 143.58
A27: QIA_01202608 | B27: MD Ariful Islam Riad | C27: 683.68 | D27: 143.58
A28: QIA_01202609 | B28: MD Ariful Islam Riad | C28: 683.68 | D28: 143.58
A29: QIA_01202610 | B29: MD Ariful Islam Riad | C29: 683.68 | D29: 143.58
A30: QIA_01202611 | B30: MD Ariful Islam Riad | C30: 683.68 | D30: 143.58
A31: QIA_01202612 | B31: Emdadullah | C31: 683.68 | D31: 143.58
... A68: QIA_01202649 | B68: Johir Raihan | C68: 683.68 | D68: 143.58
A69: Total | C69: =SUM(C20:C68) -> 33500.32 | D69: =SUM(D20:D68) -> 7035.42
A74: Installment Payment Schedule (12 Months)
A75: Month | B75: Installment (BDT) | C75: Remaining Due (BDT) | D75: Remarks
A76: 46143 | B76: 3400 | C76: =40535-Sum(B40:B76) -> 37135 | D76: 3426050400025415
A77: 46174 | B77: 3400 | C77: =40535-Sum(B41:B77) -> 33735 | D77: 3426060700068465
A78: 46204 | B78: 3400 | C78: =40535-Sum(B42:B78) -> 30335 | D78: Cash (Reciept No: 16)
A79: 46235 | B79: 3400 | C79: =40535-Sum(B43:B79) -> 26935 | D79: 9626080600016286
A80: 46266 | C80: =40535-Sum(B44:B80) -> 26935
A81: 46296 | C81: =40535-Sum(B45:B81) -> 26935
A82: 46327 | C82: =40535-Sum(B46:B82) -> 26935
A83: 46357 | C83: =40535-Sum(B47:B83) -> 26935
A84: 46388 | C84: =40535-Sum(B48:B84) -> 26935
A85: 46419 | C85: =40535-Sum(B49:B85) -> 26935
A86: 46447 | C86: =40535-Sum(B50:B86) -> 26935
A87: 46478 | C87: =40535-Sum(B51:B87) -> 26935 | D87: Final Payment
...

Sheet Minhaj Sales Portfolio-5
A1: Sales Portfolio-5
A4: Invoice No. | B4: QIA-INV-05
A5: Issue Date | B5: 46179
A6: Customer Name | B6: Sakibul Islam
A7: Phone Number | B7: 1789295203
A8: Adress | B8: Monohardi, Narsingdi
A11: Sl | B11: Item Description | C11: Quantity | D11: Unit Price | E11: Total Price | F11: Cost Price | G11: Gross Profit
A12: 1 | B12: Laptop, Chair, Furniture | E12: 2,90,000 | F12: 2,50,000 | G12: 40000
A13: Grand Total: (Two Lac Ninety Thousand Taka Only) | E13: 2,90,000
D14: Amount Paid | E14: 0
D15: Amount Due | E15: 2,90,000
A19: ID | B19: Name | C19: Invested Amount | D19: Estimated Gross Profit
A20: QIA_01202601 | B20: Mohammad Jonaid
A21: QIA_01202602 | B21: Mohammad Jonaid
A22: QIA_01202603 | B22: Mohammad Jonaid
A23: QIA_01202604 | B23: Abdullah Ibne Kabir Fahim
A24: QIA_01202605 | B24: Abdullah Ibne Kabir Fahim
A25: QIA_01202606 | B25: Abdur Rahim
A26: QIA_01202607 | B26: Abdur Rahim
A27: QIA_01202608 | B27: MD Ariful Islam Riad
A28: QIA_01202609 | B28: MD Ariful Islam Riad
A29: QIA_01202610 | B29: MD Ariful Islam Riad
A30: QIA_01202611 | B30: MD Ariful Islam Riad
A31: QIA_01202612 | B31: Emdadullah
... A68: QIA_01202649 | B68: Johir Raihan
A69: Total
A74: Installment Payment Schedule (12 Months)
A75: Month | B75: Installment (BDT) | C75: Remaining Due (BDT) | D75: Remarks
A76: 46204 | B76: 25000 | C76: =290000-Sum(B44:B76) -> 265000 | D76: Cash (Reciept No: 15)
A77: 46235 | B77: 25000 | C77: =290000-Sum(B45:B77) -> 240000 | D77: 9626081100082784
A78: 46266 | C78: =290000-Sum(B46:B78) -> 240000
A79: 46296 | C79: =290000-Sum(B47:B79) -> 240000
A80: 46327 | C80: =290000-Sum(B48:B80) -> 240000
A81: 46357 | C81: =290000-Sum(B49:B81) -> 240000
A82: 46388 | C82: =290000-Sum(B50:B82) -> 240000
A83: 46419 | C83: =290000-Sum(B51:B83) -> 240000
A84: 46447 | C84: =290000-Sum(B52:B84) -> 240000
A85: 46478 | C85: =290000-Sum(B53:B85) -> 240000
A86: 46508 | C86: =290000-Sum(B54:B86) -> 240000
A87: 46539 | C87: =290000-Sum(B55:B87) -> 240000
...

Sheet Riad Sales Portfolio-6
A1: Sales Portfolio-6
A4: Invoice No. | B4: QIA-INV-06
A5: Issue Date | B5: 46204
A6: Customer Name | B6: Ariful Islam Riad
A7: Phone Number | B7: 01632-343323
A8: Adress | B8: Katiadi, Kishorganj
A11: Sl | B11: Item Description | C11: Quantity | D11: Unit Price | E11: Total Price | F11: Cost Price | G11: Gross Profit
A12: 1 | B12: Bike (HONDA SP 125) | C12: 1 | D12: 1,93,720 | E12: 1,93,720 | F12: 167000 | G12: 26720
A13: Grand Total: (One Lac Ninety Three Thousand Seven Hundred Twenty Taka Only) | E13: 1,93,720
D14: Amount Paid | E14: 0
D15: Amount Due | E15: 1,93,720
A19: ID | B19: Name | C19: Invested Amount | D19: Estimated Gross Profit
A69: Total
A74: Installment Payment Schedule (12 Months)
A75: Month | B75: Installment (BDT) | C75: Remaining Due (BDT) | D75: Remarks
A76: 46235 | B76: 16150 | C76: =193720-Sum(B44:B76) -> 177570 | D76: 9626080300113790
A77: 46266 | C77: =193720-Sum(B45:B77) -> 177570
A78: 46296 | C78: =193720-Sum(B46:B78) -> 177570
A79: 46327 | C79: =193720-Sum(B47:B79) -> 177570
A80: 46357 | C80: =193720-Sum(B48:B80) -> 177570
A81: 46388 | C81: =193720-Sum(B49:B81) -> 177570
A82: 46419 | C82: =193720-Sum(B50:B82) -> 177570
A83: 46447 | C83: =193720-Sum(B51:B83) -> 177570
A84: 46478 | C84: =193720-Sum(B52:B84) -> 177570
A85: 46508 | C85: =193720-Sum(B53:B85) -> 177570
A86: 46539 | C86: =193720-Sum(B54:B86) -> 177570
A87: 46569 | C87: =193720-Sum(B55:B87) -> 177570
A88: 46569 | C88: =193720-Sum(B56:B88) -> 177570 | D88: Final Payment
A89: Total Payment | B89: =SUM(B76:B88) -> 16150
